 * Serving Flask app 'app'
 * Debug mode: off
Error sending initial data: 'DatabaseManager' object has no attribute 'get_connection'
Error sending initial data: 'DatabaseManager' object has no attribute 'get_connection'
Error sending initial data: 'DatabaseManager' object has no attribute 'get_connection'
Error sending initial data: 'DatabaseManager' object has no attribute 'get_connection'
Error sending initial data: 'DatabaseManager' object has no attribute 'get_connection'
Error sending initial data: 'DatabaseManager' object has no attribute 'get_connection'
Error sending initial data: 'DatabaseManager' object has no attribute 'get_connection'
Error sending initial data: 'DatabaseManager' object has no attribute 'get_connection'
Error sending initial data: 'DatabaseManager' object has no attribute 'get_connection'
Error sending initial data: 'DatabaseManager' object has no attribute 'get_connection'
Error sending initial data: 'DatabaseManager' object has no attribute 'get_connection'
Error sending initial data: 'DatabaseManager' object has no attribute 'get_connection'
2025-09-28 11:35:56,623 - werkzeug - ERROR - Error on request:
Traceback (most recent call last):
  File "/home/andrei/aMonitoringHub/venv/lib/python3.12/site-packages/werkzeug/serving.py", line 334, in execute
    write(data)
  File "/home/andrei/aMonitoringHub/venv/lib/python3.12/site-packages/werkzeug/serving.py", line 306, in write
    self.wfile.write(hex(len(data))[2:].encode())
  File "/usr/lib/python3.12/socketserver.py", line 840, in write
    self._sock.sendall(b)
BrokenPipeError: [Errno 32] Broken pipe

During handling of the above exception, another exception occurred:

Traceback (most recent call last):
  File "/home/andrei/aMonitoringHub/venv/lib/python3.12/site-packages/werkzeug/serving.py", line 370, in run_wsgi
    execute(self.server.app)
  File "/home/andrei/aMonitoringHub/venv/lib/python3.12/site-packages/werkzeug/serving.py", line 367, in execute
    application_iter.close()
  File "/home/andrei/aMonitoringHub/venv/lib/python3.12/site-packages/werkzeug/wsgi.py", line 260, in close
    callback()
  File "/home/andrei/aMonitoringHub/venv/lib/python3.12/site-packages/werkzeug/wrappers/response.py", line 403, in close
    self.response.close()
RuntimeError: generator ignored GeneratorExit
2025-09-28 11:35:56,625 - werkzeug - ERROR - Error on request:
Traceback (most recent call last):
  File "/home/andrei/aMonitoringHub/venv/lib/python3.12/site-packages/werkzeug/serving.py", line 334, in execute
    write(data)
  File "/home/andrei/aMonitoringHub/venv/lib/python3.12/site-packages/werkzeug/serving.py", line 306, in write
    self.wfile.write(hex(len(data))[2:].encode())
  File "/usr/lib/python3.12/socketserver.py", line 840, in write
    self._sock.sendall(b)
BrokenPipeError: [Errno 32] Broken pipe

During handling of the above exception, another exception occurred:

Traceback (most recent call last):
  File "/home/andrei/aMonitoringHub/venv/lib/python3.12/site-packages/werkzeug/serving.py", line 370, in run_wsgi
    execute(self.server.app)
  File "/home/andrei/aMonitoringHub/venv/lib/python3.12/site-packages/werkzeug/serving.py", line 367, in execute
    application_iter.close()
  File "/home/andrei/aMonitoringHub/venv/lib/python3.12/site-packages/werkzeug/wsgi.py", line 260, in close
    callback()
  File "/home/andrei/aMonitoringHub/venv/lib/python3.12/site-packages/werkzeug/wrappers/response.py", line 403, in close
    self.response.close()
RuntimeError: generator ignored GeneratorExit
2025-09-28 11:35:56,627 - werkzeug - ERROR - Error on request:
Traceback (most recent call last):
  File "/home/andrei/aMonitoringHub/venv/lib/python3.12/site-packages/werkzeug/serving.py", line 334, in execute
    write(data)
  File "/home/andrei/aMonitoringHub/venv/lib/python3.12/site-packages/werkzeug/serving.py", line 306, in write
    self.wfile.write(hex(len(data))[2:].encode())
  File "/usr/lib/python3.12/socketserver.py", line 840, in write
    self._sock.sendall(b)
BrokenPipeError: [Errno 32] Broken pipe

During handling of the above exception, another exception occurred:

Traceback (most recent call last):
  File "/home/andrei/aMonitoringHub/venv/lib/python3.12/site-packages/werkzeug/serving.py", line 370, in run_wsgi
    execute(self.server.app)
  File "/home/andrei/aMonitoringHub/venv/lib/python3.12/site-packages/werkzeug/serving.py", line 367, in execute
    application_iter.close()
  File "/home/andrei/aMonitoringHub/venv/lib/python3.12/site-packages/werkzeug/wsgi.py", line 260, in close
    callback()
  File "/home/andrei/aMonitoringHub/venv/lib/python3.12/site-packages/werkzeug/wrappers/response.py", line 403, in close
    self.response.close()
RuntimeError: generator ignored GeneratorExit
2025-09-28 11:35:56,629 - werkzeug - ERROR - Error on request:
Traceback (most recent call last):
  File "/home/andrei/aMonitoringHub/venv/lib/python3.12/site-packages/werkzeug/serving.py", line 334, in execute
    write(data)
  File "/home/andrei/aMonitoringHub/venv/lib/python3.12/site-packages/werkzeug/serving.py", line 306, in write
    self.wfile.write(hex(len(data))[2:].encode())
  File "/usr/lib/python3.12/socketserver.py", line 840, in write
    self._sock.sendall(b)
BrokenPipeError: [Errno 32] Broken pipe

During handling of the above exception, another exception occurred:

Traceback (most recent call last):
  File "/home/andrei/aMonitoringHub/venv/lib/python3.12/site-packages/werkzeug/serving.py", line 370, in run_wsgi
    execute(self.server.app)
  File "/home/andrei/aMonitoringHub/venv/lib/python3.12/site-packages/werkzeug/serving.py", line 367, in execute
    application_iter.close()
  File "/home/andrei/aMonitoringHub/venv/lib/python3.12/site-packages/werkzeug/wsgi.py", line 260, in close
    callback()
  File "/home/andrei/aMonitoringHub/venv/lib/python3.12/site-packages/werkzeug/wrappers/response.py", line 403, in close
    self.response.close()
RuntimeError: generator ignored GeneratorExit
Error sending initial data: 'DatabaseManager' object has no attribute 'get_connection'
Error sending initial data: 'DatabaseManager' object has no attribute 'get_connection'
Error sending initial data: 'DatabaseManager' object has no attribute 'get_connection'
Error sending initial data: 'DatabaseManager' object has no attribute 'get_connection'
Error sending initial data: 'DatabaseManager' object has no attribute 'get_connection'
Error sending initial data: 'DatabaseManager' object has no attribute 'get_connection'
Error sending initial data: 'DatabaseManager' object has no attribute 'get_connection'
Error sending initial data: 'DatabaseManager' object has no attribute 'get_connection'
Error sending initial data: 'DatabaseManager' object has no attribute 'get_connection'
Error sending initial data: 'DatabaseManager' object has no attribute 'get_connection'
Error sending initial data: 'DatabaseManager' object has no attribute 'get_connection'
2025-09-28 11:55:34,971 - werkzeug - ERROR - Error on request:
Traceback (most recent call last):
  File "/home/andrei/aMonitoringHub/venv/lib/python3.12/site-packages/werkzeug/serving.py", line 334, in execute
    write(data)
  File "/home/andrei/aMonitoringHub/venv/lib/python3.12/site-packages/werkzeug/serving.py", line 306, in write
    self.wfile.write(hex(len(data))[2:].encode())
  File "/usr/lib/python3.12/socketserver.py", line 840, in write
    self._sock.sendall(b)
BrokenPipeError: [Errno 32] Broken pipe

During handling of the above exception, another exception occurred:

Traceback (most recent call last):
  File "/home/andrei/aMonitoringHub/venv/lib/python3.12/site-packages/werkzeug/serving.py", line 370, in run_wsgi
    execute(self.server.app)
  File "/home/andrei/aMonitoringHub/venv/lib/python3.12/site-packages/werkzeug/serving.py", line 367, in execute
    application_iter.close()
  File "/home/andrei/aMonitoringHub/venv/lib/python3.12/site-packages/werkzeug/wsgi.py", line 260, in close
    callback()
  File "/home/andrei/aMonitoringHub/venv/lib/python3.12/site-packages/werkzeug/wrappers/response.py", line 403, in close
    self.response.close()
RuntimeError: generator ignored GeneratorExit
2025-09-28 11:55:34,973 - werkzeug - ERROR - Error on request:
Traceback (most recent call last):
  File "/home/andrei/aMonitoringHub/venv/lib/python3.12/site-packages/werkzeug/serving.py", line 334, in execute
    write(data)
  File "/home/andrei/aMonitoringHub/venv/lib/python3.12/site-packages/werkzeug/serving.py", line 306, in write
    self.wfile.write(hex(len(data))[2:].encode())
  File "/usr/lib/python3.12/socketserver.py", line 840, in write
    self._sock.sendall(b)
BrokenPipeError: [Errno 32] Broken pipe

During handling of the above exception, another exception occurred:

Traceback (most recent call last):
  File "/home/andrei/aMonitoringHub/venv/lib/python3.12/site-packages/werkzeug/serving.py", line 370, in run_wsgi
    execute(self.server.app)
  File "/home/andrei/aMonitoringHub/venv/lib/python3.12/site-packages/werkzeug/serving.py", line 367, in execute
    application_iter.close()
  File "/home/andrei/aMonitoringHub/venv/lib/python3.12/site-packages/werkzeug/wsgi.py", line 260, in close
    callback()
  File "/home/andrei/aMonitoringHub/venv/lib/python3.12/site-packages/werkzeug/wrappers/response.py", line 403, in close
    self.response.close()
RuntimeError: generator ignored GeneratorExit
Error sending initial data: 'DatabaseManager' object has no attribute 'get_connection'
Error sending initial data: 'DatabaseManager' object has no attribute 'get_connection'
Error sending initial data: 'DatabaseManager' object has no attribute 'get_connection'
Error sending initial data: 'DatabaseManager' object has no attribute 'get_connection'
2025-09-28 11:57:05,603 - werkzeug - ERROR - Error on request:
Traceback (most recent call last):
  File "/home/andrei/aMonitoringHub/venv/lib/python3.12/site-packages/werkzeug/serving.py", line 334, in execute
    write(data)
  File "/home/andrei/aMonitoringHub/venv/lib/python3.12/site-packages/werkzeug/serving.py", line 306, in write
    self.wfile.write(hex(len(data))[2:].encode())
  File "/usr/lib/python3.12/socketserver.py", line 840, in write
    self._sock.sendall(b)
BrokenPipeError: [Errno 32] Broken pipe

During handling of the above exception, another exception occurred:

Traceback (most recent call last):
  File "/home/andrei/aMonitoringHub/venv/lib/python3.12/site-packages/werkzeug/serving.py", line 370, in run_wsgi
    execute(self.server.app)
  File "/home/andrei/aMonitoringHub/venv/lib/python3.12/site-packages/werkzeug/serving.py", line 367, in execute
    application_iter.close()
  File "/home/andrei/aMonitoringHub/venv/lib/python3.12/site-packages/werkzeug/wsgi.py", line 260, in close
    callback()
  File "/home/andrei/aMonitoringHub/venv/lib/python3.12/site-packages/werkzeug/wrappers/response.py", line 403, in close
    self.response.close()
RuntimeError: generator ignored GeneratorExit
Error sending initial data: 'DatabaseManager' object has no attribute 'get_connection'
Error sending initial data: 'DatabaseManager' object has no attribute 'get_connection'
Error sending initial data: 'DatabaseManager' object has no attribute 'get_connection'
Error sending initial data: 'DatabaseManager' object has no attribute 'get_connection'
Error sending initial data: 'DatabaseManager' object has no attribute 'get_connection'
Error sending initial data: 'DatabaseManager' object has no attribute 'get_connection'
Error sending initial data: 'DatabaseManager' object has no attribute 'get_connection'
Error sending initial data: 'DatabaseManager' object has no attribute 'get_connection'
